[2024-09-27T23:47:50.464+0000] {taskinstance.py:1087} INFO - Dependencies all met for <TaskInstance: welcome_dag.print_random_quote manual__2024-09-27T23:47:40.068049+00:00 [queued]>
[2024-09-27T23:47:50.477+0000] {taskinstance.py:1087} INFO - Dependencies all met for <TaskInstance: welcome_dag.print_random_quote manual__2024-09-27T23:47:40.068049+00:00 [queued]>
[2024-09-27T23:47:50.477+0000] {taskinstance.py:1283} INFO - 
--------------------------------------------------------------------------------
[2024-09-27T23:47:50.477+0000] {taskinstance.py:1284} INFO - Starting attempt 1 of 1
[2024-09-27T23:47:50.478+0000] {taskinstance.py:1285} INFO - 
--------------------------------------------------------------------------------
[2024-09-27T23:47:50.503+0000] {taskinstance.py:1304} INFO - Executing <Task(PythonOperator): print_random_quote> on 2024-09-27 23:47:40.068049+00:00
[2024-09-27T23:47:50.506+0000] {standard_task_runner.py:55} INFO - Started process 230 to run task
[2024-09-27T23:47:50.509+0000] {standard_task_runner.py:82} INFO - Running: ['airflow', 'tasks', 'run', 'welcome_dag', 'print_random_quote', 'manual__2024-09-27T23:47:40.068049+00:00', '--job-id', '11', '--raw', '--subdir', 'DAGS_FOLDER/welcome_dag.py', '--cfg-path', '/tmp/tmpeul6g3ec']
[2024-09-27T23:47:50.510+0000] {standard_task_runner.py:83} INFO - Job 11: Subtask print_random_quote
[2024-09-27T23:47:50.573+0000] {task_command.py:389} INFO - Running <TaskInstance: welcome_dag.print_random_quote manual__2024-09-27T23:47:40.068049+00:00 [running]> on host fb51fccab4c9
[2024-09-27T23:47:50.652+0000] {taskinstance.py:1513} INFO - Exporting the following env vars:
AIRFLOW_CTX_DAG_OWNER=airflow
AIRFLOW_CTX_DAG_ID=welcome_dag
AIRFLOW_CTX_TASK_ID=print_random_quote
AIRFLOW_CTX_EXECUTION_DATE=2024-09-27T23:47:40.068049+00:00
AIRFLOW_CTX_TRY_NUMBER=1
AIRFLOW_CTX_DAG_RUN_ID=manual__2024-09-27T23:47:40.068049+00:00
[2024-09-27T23:47:50.953+0000] {taskinstance.py:1772} ERROR - Task failed with exception
Traceback (most recent call last):
  File "/home/airflow/.local/lib/python3.7/site-packages/urllib3/connection.py", line 175, in _new_conn
    (self._dns_host, self.port), self.timeout, **extra_kw
  File "/home/airflow/.local/lib/python3.7/site-packages/urllib3/util/connection.py", line 72, in create_connection
    for res in socket.getaddrinfo(host, port, family, socket.SOCK_STREAM):
  File "/usr/local/lib/python3.7/socket.py", line 752, in getaddrinfo
    for res in _socket.getaddrinfo(host, port, family, type, proto, flags):
socket.gaierror: [Errno -2] Name or service not known

During handling of the above exception, another exception occurred:

Traceback (most recent call last):
  File "/home/airflow/.local/lib/python3.7/site-packages/urllib3/connectionpool.py", line 710, in urlopen
    chunked=chunked,
  File "/home/airflow/.local/lib/python3.7/site-packages/urllib3/connectionpool.py", line 386, in _make_request
    self._validate_conn(conn)
  File "/home/airflow/.local/lib/python3.7/site-packages/urllib3/connectionpool.py", line 1042, in _validate_conn
    conn.connect()
  File "/home/airflow/.local/lib/python3.7/site-packages/urllib3/connection.py", line 358, in connect
    self.sock = conn = self._new_conn()
  File "/home/airflow/.local/lib/python3.7/site-packages/urllib3/connection.py", line 187, in _new_conn
    self, "Failed to establish a new connection: %s" % e
urllib3.exceptions.NewConnectionError: <urllib3.connection.HTTPSConnection object at 0x7f7bc59791d0>: Failed to establish a new connection: [Errno -2] Name or service not known

During handling of the above exception, another exception occurred:

Traceback (most recent call last):
  File "/home/airflow/.local/lib/python3.7/site-packages/requests/adapters.py", line 499, in send
    timeout=timeout,
  File "/home/airflow/.local/lib/python3.7/site-packages/urllib3/connectionpool.py", line 788, in urlopen
    method, url, error=e, _pool=self, _stacktrace=sys.exc_info()[2]
  File "/home/airflow/.local/lib/python3.7/site-packages/urllib3/util/retry.py", line 592, in increment
    raise MaxRetryError(_pool, url, error or ResponseError(cause))
urllib3.exceptions.MaxRetryError: HTTPSConnectionPool(host='api.quotable.io', port=443): Max retries exceeded with url: /random (Caused by NewConnectionError('<urllib3.connection.HTTPSConnection object at 0x7f7bc59791d0>: Failed to establish a new connection: [Errno -2] Name or service not known'))

During handling of the above exception, another exception occurred:

Traceback (most recent call last):
  File "/home/airflow/.local/lib/python3.7/site-packages/airflow/operators/python.py", line 175, in execute
    return_value = self.execute_callable()
  File "/home/airflow/.local/lib/python3.7/site-packages/airflow/operators/python.py", line 192, in execute_callable
    return self.python_callable(*self.op_args, **self.op_kwargs)
  File "/opt/airflow/dags/welcome_dag.py", line 27, in print_random_quote
    response = requests.get('https://api.quotable.io/random')
  File "/home/airflow/.local/lib/python3.7/site-packages/requests/api.py", line 73, in get
    return request("get", url, params=params, **kwargs)
  File "/home/airflow/.local/lib/python3.7/site-packages/requests/api.py", line 59, in request
    return session.request(method=method, url=url, **kwargs)
  File "/home/airflow/.local/lib/python3.7/site-packages/requests/sessions.py", line 587, in request
    resp = self.send(prep, **send_kwargs)
  File "/home/airflow/.local/lib/python3.7/site-packages/requests/sessions.py", line 701, in send
    r = adapter.send(request, **kwargs)
  File "/home/airflow/.local/lib/python3.7/site-packages/requests/adapters.py", line 565, in send
    raise ConnectionError(e, request=request)
requests.exceptions.ConnectionError: HTTPSConnectionPool(host='api.quotable.io', port=443): Max retries exceeded with url: /random (Caused by NewConnectionError('<urllib3.connection.HTTPSConnection object at 0x7f7bc59791d0>: Failed to establish a new connection: [Errno -2] Name or service not known'))
[2024-09-27T23:47:50.967+0000] {taskinstance.py:1327} INFO - Marking task as FAILED. dag_id=welcome_dag, task_id=print_random_quote, execution_date=20240927T234740, start_date=20240927T234750, end_date=20240927T234750
[2024-09-27T23:47:50.990+0000] {standard_task_runner.py:105} ERROR - Failed to execute job 11 for task print_random_quote (HTTPSConnectionPool(host='api.quotable.io', port=443): Max retries exceeded with url: /random (Caused by NewConnectionError('<urllib3.connection.HTTPSConnection object at 0x7f7bc59791d0>: Failed to establish a new connection: [Errno -2] Name or service not known')); 230)
[2024-09-27T23:47:51.003+0000] {local_task_job.py:159} INFO - Task exited with return code 1
[2024-09-27T23:47:51.022+0000] {taskinstance.py:2582} INFO - 0 downstream tasks scheduled from follow-on schedule check
